INFO: GPU available: True (cuda), used: True
INFO:lightning.pytorch.utilities.rank_zero:GPU available: True (cuda), used: True
INFO: TPU available: False, using: 0 TPU cores
INFO:lightning.pytorch.utilities.rank_zero:TPU available: False, using: 0 TPU cores
INFO: IPU available: False, using: 0 IPUs
INFO:lightning.pytorch.utilities.rank_zero:IPU available: False, using: 0 IPUs
INFO: HPU available: False, using: 0 HPUs
INFO:lightning.pytorch.utilities.rank_zero:HPU available: False, using: 0 HPUs
INFO:pytorch_lightning.strategies.deepspeed:initializing deepspeed distributed: GLOBAL_RANK: 0, MEMBER: 1/8
Traceback (most recent call last):
  File "/usr/local/lib/python3.10/dist-packages/pytorch_lightning/trainer/call.py", line 43, in _call_and_handle_interrupt
    return trainer.strategy.launcher.launch(trainer_fn, *args, trainer=trainer, **kwargs)
  File "/usr/local/lib/python3.10/dist-packages/pytorch_lightning/strategies/launchers/subprocess_script.py", line 105, in launch
    return function(*args, **kwargs)
  File "/usr/local/lib/python3.10/dist-packages/pytorch_lightning/trainer/trainer.py", line 580, in _fit_impl
    self._run(model, ckpt_path=ckpt_path)
  File "/usr/local/lib/python3.10/dist-packages/pytorch_lightning/trainer/trainer.py", line 944, in _run
    self.__setup_profiler()
  File "/usr/local/lib/python3.10/dist-packages/pytorch_lightning/trainer/trainer.py", line 1079, in __setup_profiler
    self.profiler.setup(stage=self.state.fn, local_rank=local_rank, log_dir=self.log_dir)
  File "/usr/local/lib/python3.10/dist-packages/pytorch_lightning/trainer/trainer.py", line 1243, in log_dir
    dirpath = self.loggers[0].save_dir
AttributeError: 'bool' object has no attribute 'save_dir'
During handling of the above exception, another exception occurred:
Traceback (most recent call last):
  File "/workspace/nathan/RWKV-LM/RWKV-v5/train.py", line 322, in <module>
    trainer.fit(model, data_loader)
  File "/usr/local/lib/python3.10/dist-packages/pytorch_lightning/trainer/trainer.py", line 544, in fit
    call._call_and_handle_interrupt(
  File "/usr/local/lib/python3.10/dist-packages/pytorch_lightning/trainer/call.py", line 67, in _call_and_handle_interrupt
    logger.finalize("failed")
AttributeError: 'bool' object has no attribute 'finalize'
Traceback (most recent call last):
  File "/usr/local/lib/python3.10/dist-packages/pytorch_lightning/trainer/call.py", line 43, in _call_and_handle_interrupt
    return trainer.strategy.launcher.launch(trainer_fn, *args, trainer=trainer, **kwargs)
  File "/usr/local/lib/python3.10/dist-packages/pytorch_lightning/strategies/launchers/subprocess_script.py", line 105, in launch
    return function(*args, **kwargs)
  File "/usr/local/lib/python3.10/dist-packages/pytorch_lightning/trainer/trainer.py", line 580, in _fit_impl
    self._run(model, ckpt_path=ckpt_path)
  File "/usr/local/lib/python3.10/dist-packages/pytorch_lightning/trainer/trainer.py", line 944, in _run
    self.__setup_profiler()
  File "/usr/local/lib/python3.10/dist-packages/pytorch_lightning/trainer/trainer.py", line 1079, in __setup_profiler
    self.profiler.setup(stage=self.state.fn, local_rank=local_rank, log_dir=self.log_dir)
  File "/usr/local/lib/python3.10/dist-packages/pytorch_lightning/trainer/trainer.py", line 1243, in log_dir
    dirpath = self.loggers[0].save_dir
AttributeError: 'bool' object has no attribute 'save_dir'
During handling of the above exception, another exception occurred:
Traceback (most recent call last):
  File "/workspace/nathan/RWKV-LM/RWKV-v5/train.py", line 322, in <module>
    trainer.fit(model, data_loader)
  File "/usr/local/lib/python3.10/dist-packages/pytorch_lightning/trainer/trainer.py", line 544, in fit
    call._call_and_handle_interrupt(
  File "/usr/local/lib/python3.10/dist-packages/pytorch_lightning/trainer/call.py", line 67, in _call_and_handle_interrupt
    logger.finalize("failed")
AttributeError: 'bool' object has no attribute 'finalize'